Workbook

Sheet Instructions
A1: EXAMPLE DATA – Northwind Retail Group AG (fictitious)
B3: About this file
B4: This workbook helps Veeam TAMs conduct a structured workload classification for a disaster recovery concept together with the customer. It is the standalone, fully manual companion to DR_Workload_Classification.html — use it when no RVTools/inventory export is available or when the customer prefers to work in a spreadsheet. The browser tool does not require this file; conversely, a completed workbook can be uploaded there for visualization.
B6: Contents
B7: 1. Import: Optionally paste the customer's raw workload list (from any source) into "Import" as a working reference, or enter workloads directly in the Workload-Register.
B8: 2. Workload-Register: Enter owner, description and the three assessment criteria Business Impact / Regulatory / Data Sensitivity (dropdowns 1–5) — protection class, target RPO/RTO and configuration recommendation are calculated automatically. Recovery Complexity (1–5) is documented alongside but never affects the score.
B9: Methodology
B10: See DR_Workload_Classification_Tool.xlsx for the full explanation of the assessment criteria (Business Impact 45%, Regulatory 35%, Data Sensitivity 20%), protection class thresholds and the Tier 0–4 naming. Recovery complexity is a separate effort/risk assessment and is not included in the score. This file uses exactly the same methodology and formulas.
B11: 5. Visualize (optional): Upload the completed workbook to "DR_Workload_Classification.html" (tab ② View classification, view-only) for class distribution, dependency network and automatic findings.

Sheet Import
A1: Import – Workload Raw List
A2: Not used in this example file — the workloads below in "Workload-Register" are already recorded. This sheet is kept as a template for your own imports.
A4: Workload Name | B4: Type (VM/Physical/DB/SaaS/Cloud) | C4: Operating System | D4: Location/Cluster | E4: Size (GiB) | F4: Responsible Team | G4: Source / Note

Sheet Class-Matrix
A1: Protection Class Matrix – Reference Table
A2: Note: "Tier" here refers exclusively to workload protection classes (this tool) and has nothing to do with the Uptime Institute tier classification (Tier I–IV) for physical data center infrastructure.
A3: Score (lower bound) | B3: Class (for formula)
A4: 0 | B4: Tier 4 – Bronze
A5: 2.5 | B5: Tier 3 – Silver
A6: 3.5 | B6: Tier 2 – Gold
A7: 4.3 | B7: Tier 1 – Platinum
A9: Recovery complexity is deliberately NOT included in the score (see the Anleitung sheet) — it is a separate effort/risk assessment.
B11: Class | C11: Target RPO | D11: Target RTO | E11: Recommended Veeam / VRO Configuration | F11: Typical Systems (Examples) | G11: Test Frequency | H11: Rank (0=strongest class)
B12: Tier 0 – Foundation | C12: ≈ 0 (continuous replication) | D12: < 30 min | E12: CDP / continuous replication, immutability on-premises + cloud, highest VRO runbook priority | F12: Active Directory, DNS, PKI, the backup infrastructure itself, core network | G12: At every DR test | H12: 0
B13: Tier 1 – Platinum | C13: < 15 min | D13: < 1 h | E13: Near-CDP replication + immutable backup, automated VRO orchestration plan with failover | F13: Core transaction systems, systems subject to DORA/NIS2, ERP core | G13: Monthly | H13: 1
B14: Tier 2 – Gold | C14: < 1 h | D14: < 4 h | E14: Multiple daily backups + optional replication, semi-automated VRO runbook | F14: Important business applications, collaboration platforms | G14: Quarterly | H14: 2
B15: Tier 3 – Silver | C15: < 4 h | D15: < 24 h | E15: Daily backup, immutability optional, standardized VRO runbook | F15: Internal line-of-business applications | G15: Semi-annually | H15: 3
B16: Tier 4 – Bronze | C16: < 24 h | D16: < 72 h / best effort | E16: Standard backup policy (daily/weekly), manual recovery acceptable | F16: Archive/test systems, non-critical services | G16: Annually (sample) | H16: 4

Sheet Workload-Register
A1: # | B1: Workload Name | C1: Owner / System Owner | D1: Business Function / Description | E1: Foundational Dependency? | F1: Business Impact (1-5) | G1: Regulatory (1-5) | H1: Data Sensitivity (1-5) | I1: Recovery Complexity (1-5) – effort/risk, NOT part of the score | J1: Score | K1: Protection Class | L1: Target RPO | M1: Target RTO | N1: Recommended Veeam/VRO Configuration | O1: Actual RPO (current) | P1: Actual RTO (current) | Q1: Gap / Actions | R1: Depends on (workload IDs, comma-separated)
A2: 1 | B2: AD-DC01 | C2: D. Krause (Network) | D2: Primary Active Directory domain controller | E2: Yes | F2: 5 | G2: 2 | H2: 2 | I2: 3 | J2: =IF(COUNTBLANK(F2:H2)>0,"",F2*0.45+G2*0.35+H2*0.2) -> 3.35 | K2: =IF(J2="","",IF(OR(E2="Ja",E2="Yes"),"Tier 0 – Foundation",INDEX('Class-Matrix'!$B$4:$B$7,MATCH(J2,'Class-Matrix'!$A$4:$A$7,1)))) -> Tier 0 – Foundation | L2: =IF(K2="","",VLOOKUP(K2,'Class-Matrix'!$B$12:$H$16,2,FALSE())) -> ≈ 0 (continuous replication) | M2: =IF(K2="","",VLOOKUP(K2,'Class-Matrix'!$B$12:$H$16,3,FALSE())) -> < 30 min | N2: =IF(K2="","",VLOOKUP(K2,'Class-Matrix'!$B$12:$H$16,4,FALSE())) -> CDP / continuous replication, immutability on-premises + cloud, highest VRO runbook priority
A3: 2 | B3: AD-DC02 | C3: T. Brandt (Application Management) | D3: Secondary Active Directory domain controller (DR data center site) | E3: Yes | F3: 5 | G3: 4 | H3: 2 | I3: 3 | J3: =IF(COUNTBLANK(F3:H3)>0,"",F3*0.45+G3*0.35+H3*0.2) -> 4.05 | K3: =IF(J3="","",IF(OR(E3="Ja",E3="Yes"),"Tier 0 – Foundation",INDEX('Class-Matrix'!$B$4:$B$7,MATCH(J3,'Class-Matrix'!$A$4:$A$7,1)))) -> Tier 0 – Foundation | L3: =IF(K3="","",VLOOKUP(K3,'Class-Matrix'!$B$12:$H$16,2,FALSE())) -> ≈ 0 (continuous replication) | M3: =IF(K3="","",VLOOKUP(K3,'Class-Matrix'!$B$12:$H$16,3,FALSE())) -> < 30 min | N3: =IF(K3="","",VLOOKUP(K3,'Class-Matrix'!$B$12:$H$16,4,FALSE())) -> CDP / continuous replication, immutability on-premises + cloud, highest VRO runbook priority
A4: 3 | B4: DNS-PRIMARY | C4: S. Meier (IT Operations) | D4: Primary DNS server for all internal zones | E4: Yes | F4: 5 | G4: 3 | H4: 2 | I4: 5 | J4: =IF(COUNTBLANK(F4:H4)>0,"",F4*0.45+G4*0.35+H4*0.2) -> 3.7 | K4: =IF(J4="","",IF(OR(E4="Ja",E4="Yes"),"Tier 0 – Foundation",INDEX('Class-Matrix'!$B$4:$B$7,MATCH(J4,'Class-Matrix'!$A$4:$A$7,1)))) -> Tier 0 – Foundation | L4: =IF(K4="","",VLOOKUP(K4,'Class-Matrix'!$B$12:$H$16,2,FALSE())) -> ≈ 0 (continuous replication) | M4: =IF(K4="","",VLOOKUP(K4,'Class-Matrix'!$B$12:$H$16,3,FALSE())) -> < 30 min | N4: =IF(K4="","",VLOOKUP(K4,'Class-Matrix'!$B$12:$H$16,4,FALSE())) -> CDP / continuous replication, immutability on-premises + cloud, highest VRO runbook priority
A5: 4 | B5: PKI-CA01 | C5: N. Hoffmann (Store IT) | D5: Certificate authority (PKI) for internal certificates | E5: Yes | F5: 5 | G5: 4 | H5: 2 | I5: 4 | J5: =IF(COUNTBLANK(F5:H5)>0,"",F5*0.45+G5*0.35+H5*0.2) -> 4.05 | K5: =IF(J5="","",IF(OR(E5="Ja",E5="Yes"),"Tier 0 – Foundation",INDEX('Class-Matrix'!$B$4:$B$7,MATCH(J5,'Class-Matrix'!$A$4:$A$7,1)))) -> Tier 0 – Foundation | L5: =IF(K5="","",VLOOKUP(K5,'Class-Matrix'!$B$12:$H$16,2,FALSE())) -> ≈ 0 (continuous replication) | M5: =IF(K5="","",VLOOKUP(K5,'Class-Matrix'!$B$12:$H$16,3,FALSE())) -> < 30 min | N5: =IF(K5="","",VLOOKUP(K5,'Class-Matrix'!$B$12:$H$16,4,FALSE())) -> CDP / continuous replication, immutability on-premises + cloud, highest VRO runbook priority
A6: 5 | B6: BACKUP-INFRA-VBR01 | C6: A. Nowak (Security) | D6: Veeam Backup & Replication server (the backup infrastructure itself) | E6: Yes | F6: 5 | G6: 3 | H6: 2 | I6: 5 | J6: =IF(COUNTBLANK(F6:H6)>0,"",F6*0.45+G6*0.35+H6*0.2) -> 3.7 | K6: =IF(J6="","",IF(OR(E6="Ja",E6="Yes"),"Tier 0 – Foundation",INDEX('Class-Matrix'!$B$4:$B$7,MATCH(J6,'Class-Matrix'!$A$4:$A$7,1)))) -> Tier 0 – Foundation | L6: =IF(K6="","",VLOOKUP(K6,'Class-Matrix'!$B$12:$H$16,2,FALSE())) -> ≈ 0 (continuous replication) | M6: =IF(K6="","",VLOOKUP(K6,'Class-Matrix'!$B$12:$H$16,3,FALSE())) -> < 30 min | N6: =IF(K6="","",VLOOKUP(K6,'Class-Matrix'!$B$12:$H$16,4,FALSE())) -> CDP / continuous replication, immutability on-premises + cloud, highest VRO runbook priority
A7: 6 | B7: CORE-SWITCH01 | C7: R. Vogel (Infrastructure) | D7: Core network switch, primary data center | E7: Yes | F7: 5 | G7: 3 | H7: 2 | I7: 4 | J7: =IF(COUNTBLANK(F7:H7)>0,"",F7*0.45+G7*0.35+H7*0.2) -> 3.7 | K7: =IF(J7="","",IF(OR(E7="Ja",E7="Yes"),"Tier 0 – Foundation",INDEX('Class-Matrix'!$B$4:$B$7,MATCH(J7,'Class-Matrix'!$A$4:$A$7,1)))) -> Tier 0 – Foundation | L7: =IF(K7="","",VLOOKUP(K7,'Class-Matrix'!$B$12:$H$16,2,FALSE())) -> ≈ 0 (continuous replication) | M7: =IF(K7="","",VLOOKUP(K7,'Class-Matrix'!$B$12:$H$16,3,FALSE())) -> < 30 min | N7: =IF(K7="","",VLOOKUP(K7,'Class-Matrix'!$B$12:$H$16,4,FALSE())) -> CDP / continuous replication, immutability on-premises + cloud, highest VRO runbook priority
A8: 7 | B8: ERP-DB01 | C8: R. Vogel (Infrastructure) | D8: SAP S/4HANA database – financial accounting, materials management | E8: No | F8: 5 | G8: 3 | H8: 3 | I8: 2 | J8: =IF(COUNTBLANK(F8:H8)>0,"",F8*0.45+G8*0.35+H8*0.2) -> 3.9 | K8: =IF(J8="","",IF(OR(E8="Ja",E8="Yes"),"Tier 0 – Foundation",INDEX('Class-Matrix'!$B$4:$B$7,MATCH(J8,'Class-Matrix'!$A$4:$A$7,1)))) -> Tier 2 – Gold | L8: =IF(K8="","",VLOOKUP(K8,'Class-Matrix'!$B$12:$H$16,2,FALSE())) -> < 1 h | M8: =IF(K8="","",VLOOKUP(K8,'Class-Matrix'!$B$12:$H$16,3,FALSE())) -> < 4 h | N8: =IF(K8="","",VLOOKUP(K8,'Class-Matrix'!$B$12:$H$16,4,FALSE())) -> Multiple daily backups + optional replication, semi-automated VRO runbook | R8: 1,3
A9: 8 | B9: PAYMENT-DB01 | C9: J. Keller (Database Team) | D9: Payment processing database (PCI-relevant) | E9: No | F9: 5 | G9: 4 | H9: 5 | I9: 2 | J9: =IF(COUNTBLANK(F9:H9)>0,"",F9*0.45+G9*0.35+H9*0.2) -> 4.65 | K9: =IF(J9="","",IF(OR(E9="Ja",E9="Yes"),"Tier 0 – Foundation",INDEX('Class-Matrix'!$B$4:$B$7,MATCH(J9,'Class-Matrix'!$A$4:$A$7,1)))) -> Tier 1 – Platinum | L9: =IF(K9="","",VLOOKUP(K9,'Class-Matrix'!$B$12:$H$16,2,FALSE())) -> < 15 min | M9: =IF(K9="","",VLOOKUP(K9,'Class-Matrix'!$B$12:$H$16,3,FALSE())) -> < 1 h | N9: =IF(K9="","",VLOOKUP(K9,'Class-Matrix'!$B$12:$H$16,4,FALSE())) -> Near-CDP replication + immutable backup, automated VRO orchestration plan with failover | R9: 1,3
A10: 9 | B10: FINANCE-DB01 | C10: N. Hoffmann (Store IT) | D10: Financial accounting database (group reporting) | E10: No | F10: 5 | G10: 5 | H10: 5 | I10: 3 | J10: =IF(COUNTBLANK(F10:H10)>0,"",F10*0.45+G10*0.35+H10*0.2) -> 5 | K10: =IF(J10="","",IF(OR(E10="Ja",E10="Yes"),"Tier 0 – Foundation",INDEX('Class-Matrix'!$B$4:$B$7,MATCH(J10,'Class-Matrix'!$A$4:$A$7,1)))) -> Tier 1 – Platinum | L10: =IF(K10="","",VLOOKUP(K10,'Class-Matrix'!$B$12:$H$16,2,FALSE())) -> < 15 min | M10: =IF(K10="","",VLOOKUP(K10,'Class-Matrix'!$B$12:$H$16,3,FALSE())) -> < 1 h | N10: =IF(K10="","",VLOOKUP(K10,'Class-Matrix'!$B$12:$H$16,4,FALSE())) -> Near-CDP replication + immutable backup, automated VRO orchestration plan with failover | R10: 1,3
A11: 10 | B11: HR-DB01 | C11: T. Brandt (Application Management) | D11: HR database (payroll, personnel files) | E11: No | F11: 4 | G11: 3 | H11: 4 | I11: 3 | J11: =IF(COUNTBLANK(F11:H11)>0,"",F11*0.45+G11*0.35+H11*0.2) -> 3.65 | K11: =IF(J11="","",IF(OR(E11="Ja",E11="Yes"),"Tier 0 – Foundation",INDEX('Class-Matrix'!$B$4:$B$7,MATCH(J11,'Class-Matrix'!$A$4:$A$7,1)))) -> Tier 2 – Gold | L11: =IF(K11="","",VLOOKUP(K11,'Class-Matrix'!$B$12:$H$16,2,FALSE())) -> < 1 h | M11: =IF(K11="","",VLOOKUP(K11,'Class-Matrix'!$B$12:$H$16,3,FALSE())) -> < 4 h | N11: =IF(K11="","",VLOOKUP(K11,'Class-Matrix'!$B$12:$H$16,4,FALSE())) -> Multiple daily backups + optional replication, semi-automated VRO runbook | R11: 1,3
A12: 11 | B12: CRM-DB01 | C12: D. Krause (Network) | D12: Customer relationship management database | E12: No | F12: 4 | G12: 4 | H12: 5 | I12: 3 | J12: =IF(COUNTBLANK(F12:H12)>0,"",F12*0.45+G12*0.35+H12*0.2) -> 4.2 | K12: =IF(J12="","",IF(OR(E12="Ja",E12="Yes"),"Tier 0 – Foundation",INDEX('Class-Matrix'!$B$4:$B$7,MATCH(J12,'Class-Matrix'!$A$4:$A$7,1)))) -> Tier 2 – Gold | L12: =IF(K12="","",VLOOKUP(K12,'Class-Matrix'!$B$12:$H$16,2,FALSE())) -> < 1 h | M12: =IF(K12="","",VLOOKUP(K12,'Class-Matrix'!$B$12:$H$16,3,FALSE())) -> < 4 h | N12: =IF(K12="","",VLOOKUP(K12,'Class-Matrix'!$B$12:$H$16,4,FALSE())) -> Multiple daily backups + optional replication, semi-automated VRO runbook | R12: 1,3
A13: 12 | B13: WMS-DB01 | C13: N. Hoffmann (Store IT) | D13: Warehouse management system database | E13: No | F13: 5 | G13: 3 | H13: 4 | I13: 3 | J13: =IF(COUNTBLANK(F13:H13)>0,"",F13*0.45+G13*0.35+H13*0.2) -> 4.1 | K13: =IF(J13="","",IF(OR(E13="Ja",E13="Yes"),"Tier 0 – Foundation",INDEX('Class-Matrix'!$B$4:$B$7,MATCH(J13,'Class-Matrix'!$A$4:$A$7,1)))) -> Tier 2 – Gold | L13: =IF(K13="","",VLOOKUP(K13,'Class-Matrix'!$B$12:$H$16,2,FALSE())) -> < 1 h | M13: =IF(K13="","",VLOOKUP(K13,'Class-Matrix'!$B$12:$H$16,3,FALSE())) -> < 4 h | N13: =IF(K13="","",VLOOKUP(K13,'Class-Matrix'!$B$12:$H$16,4,FALSE())) -> Multiple daily backups + optional replication, semi-automated VRO runbook | R13: 1,3
A14: 13 | B14: LOGISTICS-DB01 | C14: C. Reiter (Finance IT) | D14: Logistics and shipping dispatch database | E14: No | F14: 4 | G14: 4 | H14: 4 | I14: 3 | J14: =IF(COUNTBLANK(F14:H14)>0,"",F14*0.45+G14*0.35+H14*0.2) -> 4 | K14: =IF(J14="","",IF(OR(E14="Ja",E14="Yes"),"Tier 0 – Foundation",INDEX('Class-Matrix'!$B$4:$B$7,MATCH(J14,'Class-Matrix'!$A$4:$A$7,1)))) -> Tier 2 – Gold | L14: =IF(K14="","",VLOOKUP(K14,'Class-Matrix'!$B$12:$H$16,2,FALSE())) -> < 1 h | M14: =IF(K14="","",VLOOKUP(K14,'Class-Matrix'!$B$12:$H$16,3,FALSE())) -> < 4 h | N14: =IF(K14="","",VLOOKUP(K14,'Class-Matrix'!$B$12:$H$16,4,FALSE())) -> Multiple daily backups + optional replication, semi-automated VRO runbook | R14: 1,3
A15: 14 | B15: ORDERMGMT-DB01 | C15: T. Brandt (Application Management) | D15: Order management database | E15: No | F15: 5 | G15: 4 | H15: 3 | I15: 3 | J15: =IF(COUNTBLANK(F15:H15)>0,"",F15*0.45+G15*0.35+H15*0.2) -> 4.25 | K15: =IF(J15="","",IF(OR(E15="Ja",E15="Yes"),"Tier 0 – Foundation",INDEX('Class-Matrix'!$B$4:$B$7,MATCH(J15,'Class-Matrix'!$A$4:$A$7,1)))) -> Tier 2 – Gold | L15: =IF(K15="","",VLOOKUP(K15,'Class-Matrix'!$B$12:$H$16,2,FALSE())) -> < 1 h | M15: =IF(K15="","",VLOOKUP(K15,'Class-Matrix'!$B$12:$H$16,3,FALSE())) -> < 4 h | N15: =IF(K15="","",VLOOKUP(K15,'Class-Matrix'!$B$12:$H$16,4,FALSE())) -> Multiple daily backups + optional replication, semi-automated VRO runbook | R15: 1,3
A16: 15 | B16: PRICING-DB01 | C16: K. Wagner (Facility IT) | D16: Pricing database | E16: No | F16: 5 | G16: 3 | H16: 3 | I16: 3 | J16: =IF(COUNTBLANK(F16:H16)>0,"",F16*0.45+G16*0.35+H16*0.2) -> 3.9 | K16: =IF(J16="","",IF(OR(E16="Ja",E16="Yes"),"Tier 0 – Foundation",INDEX('Class-Matrix'!$B$4:$B$7,MATCH(J16,'Class-Matrix'!$A$4:$A$7,1)))) -> Tier 2 – Gold | L16: =IF(K16="","",VLOOKUP(K16,'Class-Matrix'!$B$12:$H$16,2,FALSE())) -> < 1 h | M16: =IF(K16="","",VLOOKUP(K16,'Class-Matrix'!$B$12:$H$16,3,FALSE())) -> < 4 h | N16: =IF(K16="","",VLOOKUP(K16,'Class-Matrix'!$B$12:$H$16,4,FALSE())) -> Multiple daily backups + optional replication, semi-automated VRO runbook | R16: 1,3
A17: 16 | B17: INVENTORY-DB01 | C17: M. Fink (Logistics IT) | D17: Inventory management database | E17: No | F17: 5 | G17: 4 | H17: 3 | I17: 3 | J17: =IF(COUNTBLANK(F17:H17)>0,"",F17*0.45+G17*0.35+H17*0.2) -> 4.25 | K17: =IF(J17="","",IF(OR(E17="Ja",E17="Yes"),"Tier 0 – Foundation",INDEX('Class-Matrix'!$B$4:$B$7,MATCH(J17,'Class-Matrix'!$A$4:$A$7,1)))) -> Tier 2 – Gold | L17: =IF(K17="","",VLOOKUP(K17,'Class-Matrix'!$B$12:$H$16,2,FALSE())) -> < 1 h | M17: =IF(K17="","",VLOOKUP(K17,'Class-Matrix'!$B$12:$H$16,3,FALSE())) -> < 4 h | N17: =IF(K17="","",VLOOKUP(K17,'Class-Matrix'!$B$12:$H$16,4,FALSE())) -> Multiple daily backups + optional replication, semi-automated VRO runbook | R17: 1,3
A18: 17 | B18: CUSTOMERPORTAL-DB01 | C18: S. Meier (IT Operations) | D18: Customer portal database | E18: No | F18: 4 | G18: 3 | H18: 5 | I18: 2 | J18: =IF(COUNTBLANK(F18:H18)>0,"",F18*0.45+G18*0.35+H18*0.2) -> 3.85 | K18: =IF(J18="","",IF(OR(E18="Ja",E18="Yes"),"Tier 0 – Foundation",INDEX('Class-Matrix'!$B$4:$B$7,MATCH(J18,'Class-Matrix'!$A$4:$A$7,1)))) -> Tier 2 – Gold | L18: =IF(K18="","",VLOOKUP(K18,'Class-Matrix'!$B$12:$H$16,2,FALSE())) -> < 1 h | M18: =IF(K18="","",VLOOKUP(K18,'Class-Matrix'!$B$12:$H$16,3,FALSE())) -> < 4 h | N18: =IF(K18="","",VLOOKUP(K18,'Class-Matrix'!$B$12:$H$16,4,FALSE())) -> Multiple daily backups + optional replication, semi-automated VRO runbook | R18: 1,3
A19: 18 | B19: WEBSHOP-DB01 | C19: S. Meier (IT Operations) | D19: Online shop database (production system) | E19: No | F19: 5 | G19: 4 | H19: 5 | I19: 3 | J19: =IF(COUNTBLANK(F19:H19)>0,"",F19*0.45+G19*0.35+H19*0.2) -> 4.65 | K19: =IF(J19="","",IF(OR(E19="Ja",E19="Yes"),"Tier 0 – Foundation",INDEX('Class-Matrix'!$B$4:$B$7,MATCH(J19,'Class-Matrix'!$A$4:$A$7,1)))) -> Tier 1 – Platinum | L19: =IF(K19="","",VLOOKUP(K19,'Class-Matrix'!$B$12:$H$16,2,FALSE())) -> < 15 min | M19: =IF(K19="","",VLOOKUP(K19,'Class-Matrix'!$B$12:$H$16,3,FALSE())) -> < 1 h | N19: =IF(K19="","",VLOOKUP(K19,'Class-Matrix'!$B$12:$H$16,4,FALSE())) -> Near-CDP replication + immutable backup, automated VRO orchestration plan with failover | R19: 1,3
... A26: 25 | B26: ERP-APP01 | C26: C. Reiter (Finance IT) | D26: SAP S/4HANA application server 1 | E26: No | F26: 4 | G26: 4 | H26: 3 | I26: 4 | J26: =IF(COUNTBLANK(F26:H26)>0,"",F26*0.45+G26*0.35+H26*0.2) -> 3.8 | K26: =IF(J26="","",IF(OR(E26="Ja",E26="Yes"),"Tier 0 – Foundation",INDEX('Class-Matrix'!$B$4:$B$7,MATCH(J26,'Class-Matrix'!$A$4:$A$7,1)))) -> Tier 2 – Gold | L26: =IF(K26="","",VLOOKUP(K26,'Class-Matrix'!$B$12:$H$16,2,FALSE())) -> < 1 h | M26: =IF(K26="","",VLOOKUP(K26,'Class-Matrix'!$B$12:$H$16,3,FALSE())) -> < 4 h | N26: =IF(K26="","",VLOOKUP(K26,'Class-Matrix'!$B$12:$H$16,4,FALSE())) -> Multiple daily backups + optional replication, semi-automated VRO runbook | R26: 1,3,7
A27: 26 | B27: ERP-APP02 | C27: R. Vogel (Infrastructure) | D27: SAP S/4HANA application server 2 (load balancing) | E27: No | F27: 5 | G27: 4 | H27: 4 | I27: 3 | J27: =IF(COUNTBLANK(F27:H27)>0,"",F27*0.45+G27*0.35+H27*0.2) -> 4.45 | K27: =IF(J27="","",IF(OR(E27="Ja",E27="Yes"),"Tier 0 – Foundation",INDEX('Class-Matrix'!$B$4:$B$7,MATCH(J27,'Class-Matrix'!$A$4:$A$7,1)))) -> Tier 1 – Platinum | L27: =IF(K27="","",VLOOKUP(K27,'Class-Matrix'!$B$12:$H$16,2,FALSE())) -> < 15 min | M27: =IF(K27="","",VLOOKUP(K27,'Class-Matrix'!$B$12:$H$16,3,FALSE())) -> < 1 h | N27: =IF(K27="","",VLOOKUP(K27,'Class-Matrix'!$B$12:$H$16,4,FALSE())) -> Near-CDP replication + immutable backup, automated VRO orchestration plan with failover | Q27: Dependency(ies) classified weaker than this system (ERP-DB01) – clarify in workshop. | R27: 1,3,7
A28: 27 | B28: CRM-APP01 | C28: N. Hoffmann (Store IT) | D28: CRM application server | E28: No | F28: 5 | G28: 5 | H28: 3 | I28: 2 | J28: =IF(COUNTBLANK(F28:H28)>0,"",F28*0.45+G28*0.35+H28*0.2) -> 4.6 | K28: =IF(J28="","",IF(OR(E28="Ja",E28="Yes"),"Tier 0 – Foundation",INDEX('Class-Matrix'!$B$4:$B$7,MATCH(J28,'Class-Matrix'!$A$4:$A$7,1)))) -> Tier 1 – Platinum | L28: =IF(K28="","",VLOOKUP(K28,'Class-Matrix'!$B$12:$H$16,2,FALSE())) -> < 15 min | M28: =IF(K28="","",VLOOKUP(K28,'Class-Matrix'!$B$12:$H$16,3,FALSE())) -> < 1 h | N28: =IF(K28="","",VLOOKUP(K28,'Class-Matrix'!$B$12:$H$16,4,FALSE())) -> Near-CDP replication + immutable backup, automated VRO orchestration plan with failover | Q28: Dependency(ies) classified weaker than this system (CRM-DB01) – clarify in workshop. | R28: 1,3,11
A29: 28 | B29: WEBSHOP-WEB01 | C29: D. Krause (Network) | D29: Online shop web server 1 (frontend) | E29: No | F29: 4 | G29: 5 | H29: 3 | I29: 4 | J29: =IF(COUNTBLANK(F29:H29)>0,"",F29*0.45+G29*0.35+H29*0.2) -> 4.15 | K29: =IF(J29="","",IF(OR(E29="Ja",E29="Yes"),"Tier 0 – Foundation",INDEX('Class-Matrix'!$B$4:$B$7,MATCH(J29,'Class-Matrix'!$A$4:$A$7,1)))) -> Tier 2 – Gold | L29: =IF(K29="","",VLOOKUP(K29,'Class-Matrix'!$B$12:$H$16,2,FALSE())) -> < 1 h | M29: =IF(K29="","",VLOOKUP(K29,'Class-Matrix'!$B$12:$H$16,3,FALSE())) -> < 4 h | N29: =IF(K29="","",VLOOKUP(K29,'Class-Matrix'!$B$12:$H$16,4,FALSE())) -> Multiple daily backups + optional replication, semi-automated VRO runbook | R29: 1,3,18
A30: 29 | B30: WEBSHOP-WEB02 | C30: N. Hoffmann (Store IT) | D30: Online shop web server 2 (frontend, load balancing) | E30: No | F30: 5 | G30: 5 | H30: 2 | I30: 2 | J30: =IF(COUNTBLANK(F30:H30)>0,"",F30*0.45+G30*0.35+H30*0.2) -> 4.4 | K30: =IF(J30="","",IF(OR(E30="Ja",E30="Yes"),"Tier 0 – Foundation",INDEX('Class-Matrix'!$B$4:$B$7,MATCH(J30,'Class-Matrix'!$A$4:$A$7,1)))) -> Tier 1 – Platinum | L30: =IF(K30="","",VLOOKUP(K30,'Class-Matrix'!$B$12:$H$16,2,FALSE())) -> < 15 min | M30: =IF(K30="","",VLOOKUP(K30,'Class-Matrix'!$B$12:$H$16,3,FALSE())) -> < 1 h | N30: =IF(K30="","",VLOOKUP(K30,'Class-Matrix'!$B$12:$H$16,4,FALSE())) -> Near-CDP replication + immutable backup, automated VRO orchestration plan with failover | R30: 1,3,18
A31: 30 | B31: WEBSHOP-WEB03 | C31: C. Reiter (Finance IT) | D31: Online shop web server 3 (load balancing) | E31: No | F31: 4 | G31: 5 | H31: 3 | I31: 2 | J31: =IF(COUNTBLANK(F31:H31)>0,"",F31*0.45+G31*0.35+H31*0.2) -> 4.15 | K31: =IF(J31="","",IF(OR(E31="Ja",E31="Yes"),"Tier 0 – Foundation",INDEX('Class-Matrix'!$B$4:$B$7,MATCH(J31,'Class-Matrix'!$A$4:$A$7,1)))) -> Tier 2 – Gold | L31: =IF(K31="","",VLOOKUP(K31,'Class-Matrix'!$B$12:$H$16,2,FALSE())) -> < 1 h | M31: =IF(K31="","",VLOOKUP(K31,'Class-Matrix'!$B$12:$H$16,3,FALSE())) -> < 4 h | N31: =IF(K31="","",VLOOKUP(K31,'Class-Matrix'!$B$12:$H$16,4,FALSE())) -> Multiple daily backups + optional replication, semi-automated VRO runbook | R31: 1,3,18
A32: 31 | B32: WEBSHOP-API01 | C32: M. Fink (Logistics IT) | D32: Online shop API gateway | E32: No | F32: 5 | G32: 4 | H32: 3 | I32: 4 | J32: =IF(COUNTBLANK(F32:H32)>0,"",F32*0.45+G32*0.35+H32*0.2) -> 4.25 | K32: =IF(J32="","",IF(OR(E32="Ja",E32="Yes"),"Tier 0 – Foundation",INDEX('Class-Matrix'!$B$4:$B$7,MATCH(J32,'Class-Matrix'!$A$4:$A$7,1)))) -> Tier 2 – Gold | L32: =IF(K32="","",VLOOKUP(K32,'Class-Matrix'!$B$12:$H$16,2,FALSE())) -> < 1 h | M32: =IF(K32="","",VLOOKUP(K32,'Class-Matrix'!$B$12:$H$16,3,FALSE())) -> < 4 h | N32: =IF(K32="","",VLOOKUP(K32,'Class-Matrix'!$B$12:$H$16,4,FALSE())) -> Multiple daily backups + optional replication, semi-automated VRO runbook | Q32: Dependency(ies) classified weaker than this system (SEARCH-SERVICE01, CACHE-REDIS01) – clarify in workshop. | R32: 1,3,18,48,49
A33: 32 | B33: WMS-APP01 | C33: R. Vogel (Infrastructure) | D33: Warehouse management system application server | E33: No | F33: 5 | G33: 5 | H33: 3 | I33: 3 | J33: =IF(COUNTBLANK(F33:H33)>0,"",F33*0.45+G33*0.35+H33*0.2) -> 4.6 | K33: =IF(J33="","",IF(OR(E33="Ja",E33="Yes"),"Tier 0 – Foundation",INDEX('Class-Matrix'!$B$4:$B$7,MATCH(J33,'Class-Matrix'!$A$4:$A$7,1)))) -> Tier 1 – Platinum | L33: =IF(K33="","",VLOOKUP(K33,'Class-Matrix'!$B$12:$H$16,2,FALSE())) -> < 15 min | M33: =IF(K33="","",VLOOKUP(K33,'Class-Matrix'!$B$12:$H$16,3,FALSE())) -> < 1 h | N33: =IF(K33="","",VLOOKUP(K33,'Class-Matrix'!$B$12:$H$16,4,FALSE())) -> Near-CDP replication + immutable backup, automated VRO orchestration plan with failover | Q33: Dependency(ies) classified weaker than this system (WMS-DB01) – clarify in workshop. | R33: 1,3,12
A34: 33 | B34: LOGISTICS-APP01 | C34: P. Adler (HR IT) | D34: Logistics dispatch application | E34: No | F34: 5 | G34: 4 | H34: 2 | I34: 4 | J34: =IF(COUNTBLANK(F34:H34)>0,"",F34*0.45+G34*0.35+H34*0.2) -> 4.05 | K34: =IF(J34="","",IF(OR(E34="Ja",E34="Yes"),"Tier 0 – Foundation",INDEX('Class-Matrix'!$B$4:$B$7,MATCH(J34,'Class-Matrix'!$A$4:$A$7,1)))) -> Tier 2 – Gold | L34: =IF(K34="","",VLOOKUP(K34,'Class-Matrix'!$B$12:$H$16,2,FALSE())) -> < 1 h | M34: =IF(K34="","",VLOOKUP(K34,'Class-Matrix'!$B$12:$H$16,3,FALSE())) -> < 4 h | N34: =IF(K34="","",VLOOKUP(K34,'Class-Matrix'!$B$12:$H$16,4,FALSE())) -> Multiple daily backups + optional replication, semi-automated VRO runbook | R34: 1,3,13
A35: 34 | B35: ORDERMGMT-APP01 | C35: K. Wagner (Facility IT) | D35: Order management application | E35: No | F35: 4 | G35: 3 | H35: 2 | I35: 2 | J35: =IF(COUNTBLANK(F35:H35)>0,"",F35*0.45+G35*0.35+H35*0.2) -> 3.25 | K35: =IF(J35="","",IF(OR(E35="Ja",E35="Yes"),"Tier 0 – Foundation",INDEX('Class-Matrix'!$B$4:$B$7,MATCH(J35,'Class-Matrix'!$A$4:$A$7,1)))) -> Tier 3 – Silver | L35: =IF(K35="","",VLOOKUP(K35,'Class-Matrix'!$B$12:$H$16,2,FALSE())) -> < 4 h | M35: =IF(K35="","",VLOOKUP(K35,'Class-Matrix'!$B$12:$H$16,3,FALSE())) -> < 24 h | N35: =IF(K35="","",VLOOKUP(K35,'Class-Matrix'!$B$12:$H$16,4,FALSE())) -> Daily backup, immutability optional, standardized VRO runbook | R35: 1,3,14
A36: 35 | B36: PAYMENT-GATEWAY01 | C36: A. Nowak (Security) | D36: Payment gateway (credit card/payment processing) | E36: No | F36: 5 | G36: 4 | H36: 4 | I36: 4 | J36: =IF(COUNTBLANK(F36:H36)>0,"",F36*0.45+G36*0.35+H36*0.2) -> 4.45 | K36: =IF(J36="","",IF(OR(E36="Ja",E36="Yes"),"Tier 0 – Foundation",INDEX('Class-Matrix'!$B$4:$B$7,MATCH(J36,'Class-Matrix'!$A$4:$A$7,1)))) -> Tier 1 – Platinum | L36: =IF(K36="","",VLOOKUP(K36,'Class-Matrix'!$B$12:$H$16,2,FALSE())) -> < 15 min | M36: =IF(K36="","",VLOOKUP(K36,'Class-Matrix'!$B$12:$H$16,3,FALSE())) -> < 1 h | N36: =IF(K36="","",VLOOKUP(K36,'Class-Matrix'!$B$12:$H$16,4,FALSE())) -> Near-CDP replication + immutable backup, automated VRO orchestration plan with failover | Q36: Dependency(ies) classified weaker than this system (NOTIFICATION-SERVICE01) – clarify in workshop. | R36: 1,3,8,47
A37: 36 | B37: CUSTOMERPORTAL-WEB01 | C37: S. Meier (IT Operations) | D37: Customer portal web server 1 | E37: No | F37: 5 | G37: 4 | H37: 4 | I37: 2 | J37: =IF(COUNTBLANK(F37:H37)>0,"",F37*0.45+G37*0.35+H37*0.2) -> 4.45 | K37: =IF(J37="","",IF(OR(E37="Ja",E37="Yes"),"Tier 0 – Foundation",INDEX('Class-Matrix'!$B$4:$B$7,MATCH(J37,'Class-Matrix'!$A$4:$A$7,1)))) -> Tier 1 – Platinum | L37: =IF(K37="","",VLOOKUP(K37,'Class-Matrix'!$B$12:$H$16,2,FALSE())) -> < 15 min | M37: =IF(K37="","",VLOOKUP(K37,'Class-Matrix'!$B$12:$H$16,3,FALSE())) -> < 1 h | N37: =IF(K37="","",VLOOKUP(K37,'Class-Matrix'!$B$12:$H$16,4,FALSE())) -> Near-CDP replication + immutable backup, automated VRO orchestration plan with failover | Q37: Dependency(ies) classified weaker than this system (TICKETING-APP01) – clarify in workshop. | R37: 1,3,17,41
A38: 37 | B38: CUSTOMERPORTAL-WEB02 | C38: J. Keller (Database Team) | D38: Customer portal web server 2 (load balancing) | E38: No | F38: 5 | G38: 5 | H38: 2 | I38: 4 | J38: =IF(COUNTBLANK(F38:H38)>0,"",F38*0.45+G38*0.35+H38*0.2) -> 4.4 | K38: =IF(J38="","",IF(OR(E38="Ja",E38="Yes"),"Tier 0 – Foundation",INDEX('Class-Matrix'!$B$4:$B$7,MATCH(J38,'Class-Matrix'!$A$4:$A$7,1)))) -> Tier 1 – Platinum | L38: =IF(K38="","",VLOOKUP(K38,'Class-Matrix'!$B$12:$H$16,2,FALSE())) -> < 15 min | M38: =IF(K38="","",VLOOKUP(K38,'Class-Matrix'!$B$12:$H$16,3,FALSE())) -> < 1 h | N38: =IF(K38="","",VLOOKUP(K38,'Class-Matrix'!$B$12:$H$16,4,FALSE())) -> Near-CDP replication + immutable backup, automated VRO orchestration plan with failover | Q38: Dependency(ies) classified weaker than this system (CUSTOMERPORTAL-DB01, TICKETING-APP01) – clarify in workshop. | R38: 1,3,17,41
A39: 38 | B39: PRICING-APP01 | C39: N. Hoffmann (Store IT) | D39: Pricing application | E39: No | F39: 3 | G39: 4 | H39: 3 | I39: 4 | J39: =IF(COUNTBLANK(F39:H39)>0,"",F39*0.45+G39*0.35+H39*0.2) -> 3.35 | K39: =IF(J39="","",IF(OR(E39="Ja",E39="Yes"),"Tier 0 – Foundation",INDEX('Class-Matrix'!$B$4:$B$7,MATCH(J39,'Class-Matrix'!$A$4:$A$7,1)))) -> Tier 3 – Silver | L39: =IF(K39="","",VLOOKUP(K39,'Class-Matrix'!$B$12:$H$16,2,FALSE())) -> < 4 h | M39: =IF(K39="","",VLOOKUP(K39,'Class-Matrix'!$B$12:$H$16,3,FALSE())) -> < 24 h | N39: =IF(K39="","",VLOOKUP(K39,'Class-Matrix'!$B$12:$H$16,4,FALSE())) -> Daily backup, immutability optional, standardized VRO runbook | R39: 1,3,15
A40: 39 | B40: INVENTORY-APP01 | C40: M. Fink (Logistics IT) | D40: Inventory management application | E40: No | F40: 4 | G40: 3 | H40: 3 | I40: 3 | J40: =IF(COUNTBLANK(F40:H40)>0,"",F40*0.45+G40*0.35+H40*0.2) -> 3.45 | K40: =IF(J40="","",IF(OR(E40="Ja",E40="Yes"),"Tier 0 – Foundation",INDEX('Class-Matrix'!$B$4:$B$7,MATCH(J40,'Class-Matrix'!$A$4:$A$7,1)))) -> Tier 3 – Silver | L40: =IF(K40="","",VLOOKUP(K40,'Class-Matrix'!$B$12:$H$16,2,FALSE())) -> < 4 h | M40: =IF(K40="","",VLOOKUP(K40,'Class-Matrix'!$B$12:$H$16,3,FALSE())) -> < 24 h | N40: =IF(K40="","",VLOOKUP(K40,'Class-Matrix'!$B$12:$H$16,4,FALSE())) -> Daily backup, immutability optional, standardized VRO runbook | R40: 1,3,16
A41: 40 | B41: LOYALTY-APP01 | C41: L. Schuster (E-Commerce) | D41: Customer loyalty program application | E41: No | F41: 3 | G41: 2 | H41: 2 | I41: 3 | J41: =IF(COUNTBLANK(F41:H41)>0,"",F41*0.45+G41*0.35+H41*0.2) -> 2.45 | K41: =IF(J41="","",IF(OR(E41="Ja",E41="Yes"),"Tier 0 – Foundation",INDEX('Class-Matrix'!$B$4:$B$7,MATCH(J41,'Class-Matrix'!$A$4:$A$7,1)))) -> Tier 4 – Bronze | L41: =IF(K41="","",VLOOKUP(K41,'Class-Matrix'!$B$12:$H$16,2,FALSE())) -> < 24 h | M41: =IF(K41="","",VLOOKUP(K41,'Class-Matrix'!$B$12:$H$16,3,FALSE())) -> < 72 h / best effort | N41: =IF(K41="","",VLOOKUP(K41,'Class-Matrix'!$B$12:$H$16,4,FALSE())) -> Standard backup policy (daily/weekly), manual recovery acceptable | Q41: Dependency(ies) classified weaker than this system (LOYALTY-DB01) – clarify in workshop. | R41: 1,3,22
A42: 41 | B42: TICKETING-APP01 | C42: A. Nowak (Security) | D42: Service desk ticketing system | E42: No | F42: 2 | G42: 2 | H42: 4 | I42: 3 | J42: =IF(COUNTBLANK(F42:H42)>0,"",F42*0.45+G42*0.35+H42*0.2) -> 2.4 | K42: =IF(J42="","",IF(OR(E42="Ja",E42="Yes"),"Tier 0 – Foundation",INDEX('Class-Matrix'!$B$4:$B$7,MATCH(J42,'Class-Matrix'!$A$4:$A$7,1)))) -> Tier 4 – Bronze | L42: =IF(K42="","",VLOOKUP(K42,'Class-Matrix'!$B$12:$H$16,2,FALSE())) -> < 24 h | M42: =IF(K42="","",VLOOKUP(K42,'Class-Matrix'!$B$12:$H$16,3,FALSE())) -> < 72 h / best effort | N42: =IF(K42="","",VLOOKUP(K42,'Class-Matrix'!$B$12:$H$16,4,FALSE())) -> Standard backup policy (daily/weekly), manual recovery acceptable | Q42: Dependency(ies) classified weaker than this system (TICKETING-DB01) – clarify in workshop. | R42: 1,3,23
A43: 42 | B43: BI-REPORTING01 | C43: J. Keller (Database Team) | D43: Business intelligence reporting server | E43: No | F43: 2 | G43: 2 | H43: 3 | I43: 2 | J43: =IF(COUNTBLANK(F43:H43)>0,"",F43*0.45+G43*0.35+H43*0.2) -> 2.2 | K43: =IF(J43="","",IF(OR(E43="Ja",E43="Yes"),"Tier 0 – Foundation",INDEX('Class-Matrix'!$B$4:$B$7,MATCH(J43,'Class-Matrix'!$A$4:$A$7,1)))) -> Tier 4 – Bronze | L43: =IF(K43="","",VLOOKUP(K43,'Class-Matrix'!$B$12:$H$16,2,FALSE())) -> < 24 h | M43: =IF(K43="","",VLOOKUP(K43,'Class-Matrix'!$B$12:$H$16,3,FALSE())) -> < 72 h / best effort | N43: =IF(K43="","",VLOOKUP(K43,'Class-Matrix'!$B$12:$H$16,4,FALSE())) -> Standard backup policy (daily/weekly), manual recovery acceptable | R43: 1,3,20
A44: 43 | B44: ANALYTICS-APP01 | C44: R. Vogel (Infrastructure) | D44: Analytics application server | E44: No | F44: 2 | G44: 3 | H44: 4 | I44: 2 | J44: =IF(COUNTBLANK(F44:H44)>0,"",F44*0.45+G44*0.35+H44*0.2) -> 2.75 | K44: =IF(J44="","",IF(OR(E44="Ja",E44="Yes"),"Tier 0 – Foundation",INDEX('Class-Matrix'!$B$4:$B$7,MATCH(J44,'Class-Matrix'!$A$4:$A$7,1)))) -> Tier 3 – Silver | L44: =IF(K44="","",VLOOKUP(K44,'Class-Matrix'!$B$12:$H$16,2,FALSE())) -> < 4 h | M44: =IF(K44="","",VLOOKUP(K44,'Class-Matrix'!$B$12:$H$16,3,FALSE())) -> < 24 h | N44: =IF(K44="","",VLOOKUP(K44,'Class-Matrix'!$B$12:$H$16,4,FALSE())) -> Daily backup, immutability optional, standardized VRO runbook | R44: 1,3,21
A45: 44 | B45: EDI-GATEWAY01 | C45: L. Schuster (E-Commerce) | D45: EDI gateway for supplier data exchange | E45: No | F45: 3 | G45: 2 | H45: 2 | I45: 4 | J45: =IF(COUNTBLANK(F45:H45)>0,"",F45*0.45+G45*0.35+H45*0.2) -> 2.45 | K45: =IF(J45="","",IF(OR(E45="Ja",E45="Yes"),"Tier 0 – Foundation",INDEX('Class-Matrix'!$B$4:$B$7,MATCH(J45,'Class-Matrix'!$A$4:$A$7,1)))) -> Tier 4 – Bronze | L45: =IF(K45="","",VLOOKUP(K45,'Class-Matrix'!$B$12:$H$16,2,FALSE())) -> < 24 h | M45: =IF(K45="","",VLOOKUP(K45,'Class-Matrix'!$B$12:$H$16,3,FALSE())) -> < 72 h / best effort | N45: =IF(K45="","",VLOOKUP(K45,'Class-Matrix'!$B$12:$H$16,4,FALSE())) -> Standard backup policy (daily/weekly), manual recovery acceptable | R45: 1,3,34
A46: 45 | B46: B2B-PORTAL01 | C46: T. Brandt (Application Management) | D46: B2B partner portal | E46: No | F46: 3 | G46: 3 | H46: 3 | I46: 3 | J46: =IF(COUNTBLANK(F46:H46)>0,"",F46*0.45+G46*0.35+H46*0.2) -> 3 | K46: =IF(J46="","",IF(OR(E46="Ja",E46="Yes"),"Tier 0 – Foundation",INDEX('Class-Matrix'!$B$4:$B$7,MATCH(J46,'Class-Matrix'!$A$4:$A$7,1)))) -> Tier 3 – Silver | L46: =IF(K46="","",VLOOKUP(K46,'Class-Matrix'!$B$12:$H$16,2,FALSE())) -> < 4 h | M46: =IF(K46="","",VLOOKUP(K46,'Class-Matrix'!$B$12:$H$16,3,FALSE())) -> < 24 h | N46: =IF(K46="","",VLOOKUP(K46,'Class-Matrix'!$B$12:$H$16,4,FALSE())) -> Daily backup, immutability optional, standardized VRO runbook | R46: 1,3,34
...

Sheet Dashboard
A1: Dashboard – Distribution by Protection Class
A3: Protection Class | B3: Number of Workloads
A4: Tier 0 – Foundation | B4: =COUNTIF('Workload-Register'!$K$2:$K$116,A4) -> 6
A5: Tier 1 – Platinum | B5: =COUNTIF('Workload-Register'!$K$2:$K$116,A5) -> 10
A6: Tier 2 – Gold | B6: =COUNTIF('Workload-Register'!$K$2:$K$116,A6) -> 21
A7: Tier 3 – Silver | B7: =COUNTIF('Workload-Register'!$K$2:$K$116,A7) -> 30
A8: Tier 4 – Bronze | B8: =COUNTIF('Workload-Register'!$K$2:$K$116,A8) -> 38
A9: Total recorded | B9: =COUNTA('Workload-Register'!$B$2:$B$116) -> 105
A13: Example dataset (fictitious) – upload to DR_Workload_Classification.html for testing.
